[2023-05-23T17:31:04.866+0000] {taskinstance.py:1165} INFO - Dependencies all met for <TaskInstance: algolia_test.load scheduled__2019-04-01T00:00:00+00:00 [queued]>
[2023-05-23T17:31:04.873+0000] {taskinstance.py:1165} INFO - Dependencies all met for <TaskInstance: algolia_test.load scheduled__2019-04-01T00:00:00+00:00 [queued]>
[2023-05-23T17:31:04.873+0000] {taskinstance.py:1362} INFO - 
--------------------------------------------------------------------------------
[2023-05-23T17:31:04.874+0000] {taskinstance.py:1363} INFO - Starting attempt 3 of 3
[2023-05-23T17:31:04.874+0000] {taskinstance.py:1364} INFO - 
--------------------------------------------------------------------------------
[2023-05-23T17:31:04.881+0000] {taskinstance.py:1383} INFO - Executing <Task(_PythonDecoratedOperator): load> on 2019-04-01 00:00:00+00:00
[2023-05-23T17:31:04.887+0000] {standard_task_runner.py:55} INFO - Started process 14522 to run task
[2023-05-23T17:31:04.891+0000] {standard_task_runner.py:82} INFO - Running: ['***', 'tasks', 'run', 'algolia_test', 'load', 'scheduled__2019-04-01T00:00:00+00:00', '--job-id', '50', '--raw', '--subdir', 'DAGS_FOLDER/algolia-dag.py', '--cfg-path', '/tmp/tmpljqr3et5']
[2023-05-23T17:31:04.894+0000] {standard_task_runner.py:83} INFO - Job 50: Subtask load
[2023-05-23T17:31:04.909+0000] {warnings.py:110} WARNING - /home/***/.local/lib/python3.7/site-packages/***/configuration.py:545: DeprecationWarning: The sql_alchemy_conn option in [core] has been moved to the sql_alchemy_conn option in [database] - the old setting has been used, but please update your config.
  option = self._get_environment_variables(deprecated_key, deprecated_section, key, section)

[2023-05-23T17:31:04.949+0000] {task_command.py:376} INFO - Running <TaskInstance: algolia_test.load scheduled__2019-04-01T00:00:00+00:00 [running]> on host c3034470bbd8
[2023-05-23T17:31:04.996+0000] {taskinstance.py:1592} INFO - Exporting the following env vars:
AIRFLOW_CTX_DAG_OWNER=***
AIRFLOW_CTX_DAG_ID=algolia_test
AIRFLOW_CTX_TASK_ID=load
AIRFLOW_CTX_EXECUTION_DATE=2019-04-01T00:00:00+00:00
AIRFLOW_CTX_TRY_NUMBER=3
AIRFLOW_CTX_DAG_RUN_ID=scheduled__2019-04-01T00:00:00+00:00
[2023-05-23T17:31:04.998+0000] {taskinstance.py:1851} ERROR - Task failed with exception
Traceback (most recent call last):
  File "/home/airflow/.local/lib/python3.7/site-packages/airflow/decorators/base.py", line 188, in execute
    return_value = super().execute(context)
  File "/home/airflow/.local/lib/python3.7/site-packages/airflow/operators/python.py", line 175, in execute
    return_value = self.execute_callable()
  File "/home/airflow/.local/lib/python3.7/site-packages/airflow/operators/python.py", line 193, in execute_callable
    return self.python_callable(*self.op_args, **self.op_kwargs)
  File "/opt/airflow/dags/algolia-dag.py", line 50, in load
    conn = psycopg2.connect(host='localhost', database='algolia_wh', user='algolia_user', password='algolia_pwd', port='5433')
  File "/home/airflow/.local/lib/python3.7/site-packages/psycopg2/__init__.py", line 122, in connect
    conn = _connect(dsn, connection_factory=connection_factory, **kwasync)
psycopg2.OperationalError: connection to server at "localhost" (127.0.0.1), port 5433 failed: Connection refused
	Is the server running on that host and accepting TCP/IP connections?
connection to server at "localhost" (::1), port 5433 failed: Cannot assign requested address
	Is the server running on that host and accepting TCP/IP connections?

[2023-05-23T17:31:05.007+0000] {taskinstance.py:1406} INFO - Marking task as FAILED. dag_id=algolia_test, task_id=load, execution_date=20190401T000000, start_date=20230523T173104, end_date=20230523T173105
[2023-05-23T17:31:05.015+0000] {standard_task_runner.py:105} ERROR - Failed to execute job 50 for task load (connection to server at "localhost" (127.0.0.1), port 5433 failed: Connection refused
	Is the server running on that host and accepting TCP/IP connections?
connection to server at "localhost" (::1), port 5433 failed: Cannot assign requested address
	Is the server running on that host and accepting TCP/IP connections?
; 14522)
[2023-05-23T17:31:05.064+0000] {local_task_job.py:159} INFO - Task exited with return code 1
[2023-05-23T17:31:05.078+0000] {taskinstance.py:2623} INFO - 0 downstream tasks scheduled from follow-on schedule check
