[2023-05-23T19:31:39.295+0000] {taskinstance.py:1165} INFO - Dependencies all met for <TaskInstance: algolia_test.load scheduled__2019-04-01T00:00:00+00:00 [queued]>
[2023-05-23T19:31:39.301+0000] {taskinstance.py:1165} INFO - Dependencies all met for <TaskInstance: algolia_test.load scheduled__2019-04-01T00:00:00+00:00 [queued]>
[2023-05-23T19:31:39.302+0000] {taskinstance.py:1362} INFO - 
--------------------------------------------------------------------------------
[2023-05-23T19:31:39.302+0000] {taskinstance.py:1363} INFO - Starting attempt 7 of 7
[2023-05-23T19:31:39.303+0000] {taskinstance.py:1364} INFO - 
--------------------------------------------------------------------------------
[2023-05-23T19:31:39.309+0000] {taskinstance.py:1383} INFO - Executing <Task(_PythonDecoratedOperator): load> on 2019-04-01 00:00:00+00:00
[2023-05-23T19:31:39.315+0000] {standard_task_runner.py:55} INFO - Started process 15224 to run task
[2023-05-23T19:31:39.319+0000] {standard_task_runner.py:82} INFO - Running: ['***', 'tasks', 'run', 'algolia_test', 'load', 'scheduled__2019-04-01T00:00:00+00:00', '--job-id', '54', '--raw', '--subdir', 'DAGS_FOLDER/algolia-dag.py', '--cfg-path', '/tmp/tmplfzcolrn']
[2023-05-23T19:31:39.321+0000] {standard_task_runner.py:83} INFO - Job 54: Subtask load
[2023-05-23T19:31:39.332+0000] {warnings.py:110} WARNING - /home/***/.local/lib/python3.7/site-packages/***/configuration.py:545: DeprecationWarning: The sql_alchemy_conn option in [core] has been moved to the sql_alchemy_conn option in [database] - the old setting has been used, but please update your config.
  option = self._get_environment_variables(deprecated_key, deprecated_section, key, section)

[2023-05-23T19:31:39.369+0000] {task_command.py:376} INFO - Running <TaskInstance: algolia_test.load scheduled__2019-04-01T00:00:00+00:00 [running]> on host c3034470bbd8
[2023-05-23T19:31:39.415+0000] {taskinstance.py:1592} INFO - Exporting the following env vars:
AIRFLOW_CTX_DAG_OWNER=***
AIRFLOW_CTX_DAG_ID=algolia_test
AIRFLOW_CTX_TASK_ID=load
AIRFLOW_CTX_EXECUTION_DATE=2019-04-01T00:00:00+00:00
AIRFLOW_CTX_TRY_NUMBER=7
AIRFLOW_CTX_DAG_RUN_ID=scheduled__2019-04-01T00:00:00+00:00
[2023-05-23T19:31:39.416+0000] {taskinstance.py:1851} ERROR - Task failed with exception
Traceback (most recent call last):
  File "/home/airflow/.local/lib/python3.7/site-packages/airflow/decorators/base.py", line 188, in execute
    return_value = super().execute(context)
  File "/home/airflow/.local/lib/python3.7/site-packages/airflow/operators/python.py", line 175, in execute
    return_value = self.execute_callable()
  File "/home/airflow/.local/lib/python3.7/site-packages/airflow/operators/python.py", line 193, in execute_callable
    return self.python_callable(*self.op_args, **self.op_kwargs)
  File "/opt/airflow/dags/algolia-dag.py", line 50, in load
    conn = psycopg2.connect(host='127.0.0.1', database='algolia_wh', user='algolia_user', password='algolia_pwd', port='5432')
  File "/home/airflow/.local/lib/python3.7/site-packages/psycopg2/__init__.py", line 122, in connect
    conn = _connect(dsn, connection_factory=connection_factory, **kwasync)
psycopg2.OperationalError: connection to server at "127.0.0.1", port 5432 failed: Connection refused
	Is the server running on that host and accepting TCP/IP connections?

[2023-05-23T19:31:39.425+0000] {taskinstance.py:1406} INFO - Marking task as FAILED. dag_id=algolia_test, task_id=load, execution_date=20190401T000000, start_date=20230523T193139, end_date=20230523T193139
[2023-05-23T19:31:39.432+0000] {standard_task_runner.py:105} ERROR - Failed to execute job 54 for task load (connection to server at "127.0.0.1", port 5432 failed: Connection refused
	Is the server running on that host and accepting TCP/IP connections?
; 15224)
[2023-05-23T19:31:39.450+0000] {local_task_job.py:159} INFO - Task exited with return code 1
[2023-05-23T19:31:39.463+0000] {taskinstance.py:2623} INFO - 0 downstream tasks scheduled from follow-on schedule check
