[2023-05-23T12:04:33.672+0000] {taskinstance.py:1165} INFO - Dependencies all met for <TaskInstance: algolia_test.extract manual__2023-05-23T12:04:32.030947+00:00 [queued]>
[2023-05-23T12:04:33.678+0000] {taskinstance.py:1165} INFO - Dependencies all met for <TaskInstance: algolia_test.extract manual__2023-05-23T12:04:32.030947+00:00 [queued]>
[2023-05-23T12:04:33.678+0000] {taskinstance.py:1362} INFO - 
--------------------------------------------------------------------------------
[2023-05-23T12:04:33.679+0000] {taskinstance.py:1363} INFO - Starting attempt 1 of 1
[2023-05-23T12:04:33.679+0000] {taskinstance.py:1364} INFO - 
--------------------------------------------------------------------------------
[2023-05-23T12:04:33.686+0000] {taskinstance.py:1383} INFO - Executing <Task(_PythonDecoratedOperator): extract> on 2023-05-23 12:04:32.030947+00:00
[2023-05-23T12:04:33.691+0000] {standard_task_runner.py:55} INFO - Started process 133 to run task
[2023-05-23T12:04:33.695+0000] {standard_task_runner.py:82} INFO - Running: ['***', 'tasks', 'run', 'algolia_test', 'extract', 'manual__2023-05-23T12:04:32.030947+00:00', '--job-id', '5', '--raw', '--subdir', 'DAGS_FOLDER/algolia-dag.py', '--cfg-path', '/tmp/tmpo4qdm1x8']
[2023-05-23T12:04:33.696+0000] {standard_task_runner.py:83} INFO - Job 5: Subtask extract
[2023-05-23T12:04:33.744+0000] {task_command.py:376} INFO - Running <TaskInstance: algolia_test.extract manual__2023-05-23T12:04:32.030947+00:00 [running]> on host c3034470bbd8
[2023-05-23T12:04:33.789+0000] {taskinstance.py:1592} INFO - Exporting the following env vars:
AIRFLOW_CTX_DAG_OWNER=***
AIRFLOW_CTX_DAG_ID=algolia_test
AIRFLOW_CTX_TASK_ID=extract
AIRFLOW_CTX_EXECUTION_DATE=2023-05-23T12:04:32.030947+00:00
AIRFLOW_CTX_TRY_NUMBER=1
AIRFLOW_CTX_DAG_RUN_ID=manual__2023-05-23T12:04:32.030947+00:00
[2023-05-23T12:04:33.966+0000] {taskinstance.py:1851} ERROR - Task failed with exception
Traceback (most recent call last):
  File "/home/airflow/.local/lib/python3.7/site-packages/airflow/decorators/base.py", line 188, in execute
    return_value = super().execute(context)
  File "/home/airflow/.local/lib/python3.7/site-packages/airflow/operators/python.py", line 175, in execute
    return_value = self.execute_callable()
  File "/home/airflow/.local/lib/python3.7/site-packages/airflow/operators/python.py", line 193, in execute_callable
    return self.python_callable(*self.op_args, **self.op_kwargs)
  File "/opt/airflow/dags/algolia-dag.py", line 27, in extract
    for my_bucket_object in src_client.objects.all():
UnboundLocalError: local variable 'src_client' referenced before assignment
[2023-05-23T12:04:33.976+0000] {taskinstance.py:1406} INFO - Marking task as FAILED. dag_id=algolia_test, task_id=extract, execution_date=20230523T120432, start_date=20230523T120433, end_date=20230523T120433
[2023-05-23T12:04:33.985+0000] {standard_task_runner.py:105} ERROR - Failed to execute job 5 for task extract (local variable 'src_client' referenced before assignment; 133)
[2023-05-23T12:04:34.034+0000] {local_task_job.py:159} INFO - Task exited with return code 1
[2023-05-23T12:04:34.049+0000] {taskinstance.py:2623} INFO - 0 downstream tasks scheduled from follow-on schedule check
