[2023-05-23T22:18:06.251+0000] {taskinstance.py:1165} INFO - Dependencies all met for <TaskInstance: algolia_test.load scheduled__2019-04-02T00:00:00+00:00 [queued]>
[2023-05-23T22:18:06.260+0000] {taskinstance.py:1165} INFO - Dependencies all met for <TaskInstance: algolia_test.load scheduled__2019-04-02T00:00:00+00:00 [queued]>
[2023-05-23T22:18:06.261+0000] {taskinstance.py:1362} INFO - 
--------------------------------------------------------------------------------
[2023-05-23T22:18:06.261+0000] {taskinstance.py:1363} INFO - Starting attempt 3 of 3
[2023-05-23T22:18:06.262+0000] {taskinstance.py:1364} INFO - 
--------------------------------------------------------------------------------
[2023-05-23T22:18:06.272+0000] {taskinstance.py:1383} INFO - Executing <Task(_PythonDecoratedOperator): load> on 2019-04-02 00:00:00+00:00
[2023-05-23T22:18:06.280+0000] {standard_task_runner.py:55} INFO - Started process 778 to run task
[2023-05-23T22:18:06.287+0000] {standard_task_runner.py:82} INFO - Running: ['***', 'tasks', 'run', 'algolia_test', 'load', 'scheduled__2019-04-02T00:00:00+00:00', '--job-id', '104', '--raw', '--subdir', 'DAGS_FOLDER/algolia-dag.py', '--cfg-path', '/tmp/tmpb6x5liu6']
[2023-05-23T22:18:06.291+0000] {standard_task_runner.py:83} INFO - Job 104: Subtask load
[2023-05-23T22:18:06.311+0000] {warnings.py:110} WARNING - /home/***/.local/lib/python3.7/site-packages/***/configuration.py:545: DeprecationWarning: The sql_alchemy_conn option in [core] has been moved to the sql_alchemy_conn option in [database] - the old setting has been used, but please update your config.
  option = self._get_environment_variables(deprecated_key, deprecated_section, key, section)

[2023-05-23T22:18:06.368+0000] {task_command.py:376} INFO - Running <TaskInstance: algolia_test.load scheduled__2019-04-02T00:00:00+00:00 [running]> on host 7bd2786c5ce5
[2023-05-23T22:18:06.415+0000] {taskinstance.py:1592} INFO - Exporting the following env vars:
AIRFLOW_CTX_DAG_OWNER=***
AIRFLOW_CTX_DAG_ID=algolia_test
AIRFLOW_CTX_TASK_ID=load
AIRFLOW_CTX_EXECUTION_DATE=2019-04-02T00:00:00+00:00
AIRFLOW_CTX_TRY_NUMBER=3
AIRFLOW_CTX_DAG_RUN_ID=scheduled__2019-04-02T00:00:00+00:00
[2023-05-23T22:18:06.416+0000] {warnings.py:110} WARNING - /home/***/.local/lib/python3.7/site-packages/***/utils/context.py:204: AirflowContextDeprecationWarning: Accessing 'execution_date' from the template is deprecated and will be removed in a future version. Please use 'data_interval_start' or 'logical_date' instead.
  warnings.warn(_create_deprecation_warning(key, self._deprecation_replacements[key]))

[2023-05-23T22:18:06.425+0000] {logging_mixin.py:137} INFO - Index(['Unnamed: 0', 'id', 'shop_domain', 'application_id',
       'autocomplete_enabled', 'user_created_at_least_one_qr',
       'nbr_merchandised_queries', 'nbrs_pinned_items', 'showing_logo',
       'has_changed_sort_orders', 'analytics_enabled', 'use_metafields',
       'nbr_metafields', 'use_default_colors', 'show_products',
       'instant_search_enabled', 'instant_search_enabled_on_collection',
       'only_using_faceting_on_collection', 'use_merchandising_for_collection',
       'index_prefix', 'indexing_paused', 'install_channel', 'export_date',
       'has_specific_prefix'],
      dtype='object')
[2023-05-23T22:18:06.436+0000] {taskinstance.py:1851} ERROR - Task failed with exception
Traceback (most recent call last):
  File "/home/airflow/.local/lib/python3.7/site-packages/airflow/decorators/base.py", line 188, in execute
    return_value = super().execute(context)
  File "/home/airflow/.local/lib/python3.7/site-packages/airflow/operators/python.py", line 175, in execute
    return_value = self.execute_callable()
  File "/home/airflow/.local/lib/python3.7/site-packages/airflow/operators/python.py", line 193, in execute_callable
    return self.python_callable(*self.op_args, **self.op_kwargs)
  File "/opt/airflow/dags/algolia-dag.py", line 60, in load
    df.to_sql('algolia_tests', engine)
  File "/home/airflow/.local/lib/python3.7/site-packages/pandas/core/generic.py", line 2882, in to_sql
    method=method,
  File "/home/airflow/.local/lib/python3.7/site-packages/pandas/io/sql.py", line 728, in to_sql
    **engine_kwargs,
  File "/home/airflow/.local/lib/python3.7/site-packages/pandas/io/sql.py", line 1758, in to_sql
    dtype=dtype,
  File "/home/airflow/.local/lib/python3.7/site-packages/pandas/io/sql.py", line 1650, in prep_table
    table.create()
  File "/home/airflow/.local/lib/python3.7/site-packages/pandas/io/sql.py", line 858, in create
    raise ValueError(f"Table '{self.name}' already exists.")
ValueError: Table 'algolia_tests' already exists.
[2023-05-23T22:18:06.446+0000] {taskinstance.py:1406} INFO - Marking task as FAILED. dag_id=algolia_test, task_id=load, execution_date=20190402T000000, start_date=20230523T221806, end_date=20230523T221806
[2023-05-23T22:18:06.452+0000] {standard_task_runner.py:105} ERROR - Failed to execute job 104 for task load (Table 'algolia_tests' already exists.; 778)
[2023-05-23T22:18:06.502+0000] {local_task_job.py:159} INFO - Task exited with return code 1
[2023-05-23T22:18:06.516+0000] {taskinstance.py:2623} INFO - 0 downstream tasks scheduled from follow-on schedule check
