[2023-05-23T13:37:02.859+0000] {taskinstance.py:1165} INFO - Dependencies all met for <TaskInstance: algolia_test.transform scheduled__2019-04-01T00:00:00+00:00 [queued]>
[2023-05-23T13:37:02.865+0000] {taskinstance.py:1165} INFO - Dependencies all met for <TaskInstance: algolia_test.transform scheduled__2019-04-01T00:00:00+00:00 [queued]>
[2023-05-23T13:37:02.865+0000] {taskinstance.py:1362} INFO - 
--------------------------------------------------------------------------------
[2023-05-23T13:37:02.866+0000] {taskinstance.py:1363} INFO - Starting attempt 2 of 2
[2023-05-23T13:37:02.866+0000] {taskinstance.py:1364} INFO - 
--------------------------------------------------------------------------------
[2023-05-23T13:37:02.873+0000] {taskinstance.py:1383} INFO - Executing <Task(_PythonDecoratedOperator): transform> on 2019-04-01 00:00:00+00:00
[2023-05-23T13:37:02.878+0000] {standard_task_runner.py:55} INFO - Started process 4865 to run task
[2023-05-23T13:37:02.882+0000] {standard_task_runner.py:82} INFO - Running: ['***', 'tasks', 'run', 'algolia_test', 'transform', 'scheduled__2019-04-01T00:00:00+00:00', '--job-id', '35', '--raw', '--subdir', 'DAGS_FOLDER/algolia-dag.py', '--cfg-path', '/tmp/tmp158drfui']
[2023-05-23T13:37:02.884+0000] {standard_task_runner.py:83} INFO - Job 35: Subtask transform
[2023-05-23T13:37:02.895+0000] {warnings.py:110} WARNING - /home/***/.local/lib/python3.7/site-packages/***/configuration.py:545: DeprecationWarning: The sql_alchemy_conn option in [core] has been moved to the sql_alchemy_conn option in [database] - the old setting has been used, but please update your config.
  option = self._get_environment_variables(deprecated_key, deprecated_section, key, section)

[2023-05-23T13:37:02.933+0000] {task_command.py:376} INFO - Running <TaskInstance: algolia_test.transform scheduled__2019-04-01T00:00:00+00:00 [running]> on host c3034470bbd8
[2023-05-23T13:37:02.977+0000] {taskinstance.py:1592} INFO - Exporting the following env vars:
AIRFLOW_CTX_DAG_OWNER=***
AIRFLOW_CTX_DAG_ID=algolia_test
AIRFLOW_CTX_TASK_ID=transform
AIRFLOW_CTX_EXECUTION_DATE=2019-04-01T00:00:00+00:00
AIRFLOW_CTX_TRY_NUMBER=2
AIRFLOW_CTX_DAG_RUN_ID=scheduled__2019-04-01T00:00:00+00:00
[2023-05-23T13:37:02.978+0000] {warnings.py:110} WARNING - /home/***/.local/lib/python3.7/site-packages/***/utils/context.py:204: AirflowContextDeprecationWarning: Accessing 'execution_date' from the template is deprecated and will be removed in a future version. Please use 'data_interval_start' or 'logical_date' instead.
  warnings.warn(_create_deprecation_warning(key, self._deprecation_replacements[key]))

[2023-05-23T13:37:02.990+0000] {taskinstance.py:1851} ERROR - Task failed with exception
Traceback (most recent call last):
  File "/home/airflow/.local/lib/python3.7/site-packages/airflow/decorators/base.py", line 188, in execute
    return_value = super().execute(context)
  File "/home/airflow/.local/lib/python3.7/site-packages/airflow/operators/python.py", line 175, in execute
    return_value = self.execute_callable()
  File "/home/airflow/.local/lib/python3.7/site-packages/airflow/operators/python.py", line 193, in execute_callable
    return self.python_callable(*self.op_args, **self.op_kwargs)
  File "/opt/airflow/dags/algolia-dag.py", line 42, in transform
    filter_data = data[data.application_id]
  File "/home/airflow/.local/lib/python3.7/site-packages/pandas/core/frame.py", line 3464, in __getitem__
    indexer = self.loc._get_listlike_indexer(key, axis=1)[1]
  File "/home/airflow/.local/lib/python3.7/site-packages/pandas/core/indexing.py", line 1314, in _get_listlike_indexer
    self._validate_read_indexer(keyarr, indexer, axis)
  File "/home/airflow/.local/lib/python3.7/site-packages/pandas/core/indexing.py", line 1374, in _validate_read_indexer
    raise KeyError(f"None of [{key}] are in the [{axis_name}]")
KeyError: "None of [Index(['HQRLIXFEYY', '4GYGVCAEZN', '143PIYP1C5', 'I5TEW0WTC4',          nan,\n       'VJQSO4GOEQ', 'BX62FVI3M9', '3GOXRVDGNE', '3MEYGYFNXR', 'A80H4HKTZB',\n       ...\n       '6OPS9AVG35', 'Z4MFHNK4B3', '69IRL2E0N9', 'JFDF0RZ7WU', '6EVEPOJXBR',\n       'ZKW58ANJW5', '00O9STGUAW', 'UY81HZGPOQ', 'MG0NLNERWK', 'V2M61APP4S'],\n      dtype='object', length=1208)] are in the [columns]"
[2023-05-23T13:37:03.001+0000] {taskinstance.py:1406} INFO - Marking task as FAILED. dag_id=algolia_test, task_id=transform, execution_date=20190401T000000, start_date=20230523T133702, end_date=20230523T133703
[2023-05-23T13:37:03.009+0000] {standard_task_runner.py:105} ERROR - Failed to execute job 35 for task transform ("None of [Index(['HQRLIXFEYY', '4GYGVCAEZN', '143PIYP1C5', 'I5TEW0WTC4',          nan,\n       'VJQSO4GOEQ', 'BX62FVI3M9', '3GOXRVDGNE', '3MEYGYFNXR', 'A80H4HKTZB',\n       ...\n       '6OPS9AVG35', 'Z4MFHNK4B3', '69IRL2E0N9', 'JFDF0RZ7WU', '6EVEPOJXBR',\n       'ZKW58ANJW5', '00O9STGUAW', 'UY81HZGPOQ', 'MG0NLNERWK', 'V2M61APP4S'],\n      dtype='object', length=1208)] are in the [columns]"; 4865)
[2023-05-23T13:37:03.054+0000] {local_task_job.py:159} INFO - Task exited with return code 1
[2023-05-23T13:37:03.068+0000] {taskinstance.py:2623} INFO - 0 downstream tasks scheduled from follow-on schedule check
